2024-08-09 06:20:37 | INFO    | __main__:stash:131 | run - {'image': '20231121', 'version': '0.10.1.post2', 'role': 'EpicPlayer', 'headless': True}
2024-08-09 06:20:45 | INFO    | __main__:claim_epic_games:97 | Try to flush cookie - {'task': 'claim_epic_games'}
2024-08-09 06:20:47 | INFO    | epic_games.agent:_login:237 | login-with-email - {'url': 'https://www.epicgames.com/id/login?lang=en-US&noHostRedirect=true&redirectUrl=https://store.epicgames.com/en-US/free-games&__cf_chl_rt_tk=MeqkpfvmYGKlMFNGsLrWTVRS_nI1CaQeCeAdZyDAxrE-1723155647-0.0.1.1-5546'}
2024-08-09 06:21:17 | WARNING    | epic_games.agent:authorize:266 | 执行超时 - {'task': 'authorize', 'retry': 0}
2024-08-09 06:21:18 | ERROR    | __main__:run:158 | An error has been caught in function 'run', process 'MainProcess' (3728), thread 'MainThread' (139762587077504): - {}
Traceback (most recent call last):
  File "/home/runner/work/epicfree/epicfree/epic/src/claim.py", line 162, in <module>
    asyncio.run(run())
  File "/opt/hostedtoolcache/Python/3.10.14/x64/lib/python3.10/asyncio/runners.py", line 44, in run
    return loop.run_until_complete(main)
  File "/opt/hostedtoolcache/Python/3.10.14/x64/lib/python3.10/asyncio/base_events.py", line 636, in run_until_complete
    self.run_forever()
  File "/opt/hostedtoolcache/Python/3.10.14/x64/lib/python3.10/asyncio/base_events.py", line 603, in run_forever
    self._run_once()
  File "/opt/hostedtoolcache/Python/3.10.14/x64/lib/python3.10/asyncio/base_events.py", line 1909, in _run_once
    handle._run()
  File "/opt/hostedtoolcache/Python/3.10.14/x64/lib/python3.10/asyncio/events.py", line 80, in _run
    self._context.run(self._callback, *self._args)
> File "/home/runner/work/epicfree/epicfree/epic/src/claim.py", line 158, in run
    await agent.stash()
  File "/home/runner/work/epicfree/epicfree/epic/src/claim.py", line 151, in stash
    await self.claim_epic_games(context)
  File "/home/runner/work/epicfree/epicfree/epic/src/claim.py", line 98, in claim_epic_games
    if await epic.authorize(page):
  File "/home/runner/work/epicfree/epicfree/epic/src/epic_games/agent.py", line 260, in authorize
    match await self._login(page):
  File "/home/runner/work/epicfree/epicfree/epic/src/epic_games/agent.py", line 234, in _login
    await page.goto(URL_CLAIM, wait_until="domcontentloaded")
  File "/opt/hostedtoolcache/Python/3.10.14/x64/lib/python3.10/site-packages/playwright/async_api/_generated.py", line 8818, in goto
    await self._impl_obj.goto(
  File "/opt/hostedtoolcache/Python/3.10.14/x64/lib/python3.10/site-packages/playwright/_impl/_page.py", line 524, in goto
    return await self._main_frame.goto(**locals_to_params(locals()))
  File "/opt/hostedtoolcache/Python/3.10.14/x64/lib/python3.10/site-packages/playwright/_impl/_frame.py", line 145, in goto
    await self._channel.send("goto", locals_to_params(locals()))
  File "/opt/hostedtoolcache/Python/3.10.14/x64/lib/python3.10/site-packages/playwright/_impl/_connection.py", line 59, in send
    return await self._connection.wrap_api_call(
  File "/opt/hostedtoolcache/Python/3.10.14/x64/lib/python3.10/site-packages/playwright/_impl/_connection.py", line 514, in wrap_api_call
    raise rewrite_error(error, f"{parsed_st['apiName']}: {error}") from None
playwright._impl._errors.Error: Page.goto: NS_ERROR_ABORT
Call log:
navigating to "https://store.epicgames.com/en-US/free-games", waiting until "domcontentloaded"

